Workbook

Sheet Итоги
A1: Cobrowsing → Full Production (greenfield rewrite) — оценка трудозатрат
A2: Переработка от 08.07.2026 · PoC не переиспользуется · чел-дни · EUR
A4: Ключевые допущения (обновлено)
A5: Базис | B5: PoC в помойку: iOS SDK, token-server, оператор-UI — пишем с нуля
A6: iOS / Android | B6: оба SDK с нуля, production-grade (capture, publish, state machine, packaging, тесты)
A7: Token-server | B7: с нуля: session API, коды, JWT, anti-hijack, rate-limit, logging
A8: Оператор | B8: встраиваем в существующий React-проект; auth/SSO переиспользуем из host-app
A9: Web-клиент | B9: клиентский screen-share (getDisplayMedia) — в скоупе
A10: Инфра | B10: greenfield (LiveKit/Caddy/Redis/compose/CI — с нуля)
A11: Масштаб / SLA | B11: до 50 сессий; один регион, best-effort ~99%; GDPR-гигиена
A12: Вне скоупа | B12: PII-redaction, настоящий remote control, DOM-mirroring, HA, пентест/сертификация
A13: Архитектура | B13: решения и уроки PoC сохраняем — переписываем реализацию, не дизайн
A15: Параметры модели (входные)
A16: PM / координация, % | B16: 0.1
A17: Контингенси, % | B17: 0.16
A18: Диапазон: низ, × | B18: 0.87
A19: Диапазон: верх, × | B19: 1.15
A21: Итог по программе (чел-дни)
A22: Ядро (core) | B22: ='Оценка (WBS)'!J40 -> 132.5
A23: + PM / координация | B23: =B22*B16 -> 13.25
A24: + Контингенси | B24: =B22*B17 -> 21.2
A25: Итого (likely) | B25: =B22+B23+B24 -> 166.95
A26: Итого — нижняя оценка | B26: =B25*B18 -> 145.2465
A27: Итого — верхняя оценка | B27: =B25*B19 -> 191.9925
A29: Раскладка по фазам
A30: Фаза | B30: Чел-дни | C30: Доля
A31: Фаза 0 — Фундамент (инфра + token-server с нуля) | B31: =SUM('Оценка (WBS)'!J4:J18) -> 52 | C31: =B31/$B$22 -> 0.39245283
A32: Фаза 1 — iOS-клиент (с нуля) | B32: =SUM('Оценка (WBS)'!J19:J27) -> 24 | C32: =B32/$B$22 -> 0.18113208
A33: Фаза 2 — Android-клиент (с нуля) | B33: =SUM('Оценка (WBS)'!J28:J29) -> 19.5 | C33: =B33/$B$22 -> 0.14716981
A34: Фаза 3 — Оператор в существующем React | B34: =SUM('Оценка (WBS)'!J30:J35) -> 15.5 | C34: =B34/$B$22 -> 0.11698113
A35: Фаза 4 — Web-клиент (screen-share) | B35: =SUM('Оценка (WBS)'!J36:J37) -> 15.5 | C35: =B35/$B$22 -> 0.11698113
A36: Фаза 5 — Кросс-платформенный launch | B36: =SUM('Оценка (WBS)'!J38:J39) -> 6 | C36: =B36/$B$22 -> 0.045283019
A37: Итого (core) | B37: =SUM(B31:B36) -> 132.5 | C37: =B37/$B$22 -> 1
A40: Роли: трудозатраты и стоимость
A41: Роль | B41: Чел-дни | C41: Ставка, €/день (образец) | D41: Стоимость, €
A42: iOS | B42: ='Оценка (WBS)'!D40 -> 20 | C42: 400 | D42: =B42*C42 -> 8000
A43: Android | B43: ='Оценка (WBS)'!E40 -> 15.5 | C43: 400 | D43: =B43*C43 -> 6200
A44: Backend | B44: ='Оценка (WBS)'!F40 -> 24 | C44: 400 | D44: =B44*C44 -> 9600
A45: Frontend / Web | B45: ='Оценка (WBS)'!G40 -> 27.5 | C45: 400 | D45: =B45*C45 -> 11000
A46: DevOps / SRE | B46: ='Оценка (WBS)'!H40 -> 26 | C46: 450 | D46: =B46*C46 -> 11700
...

Sheet Оценка (WBS)
A1: Детальная оценка (WBS, greenfield) — чел-дни по ролям
A3: Фаза | B3: Воркстрим / задача | C3: Ключевые роли | D3: iOS | E3: Android | F3: Backend | G3: Frontend/Web | H3: DevOps | I3: QA | J3: Итого
A4: Фаза 0 — Фундамент (инфра + token-server с нуля) | B4: Базовая инфра с нуля (LiveKit+Caddy+Redis+compose, host-mode сеть, TURN, firewall, TLS) | C4: DevOps | D4: 0 | E4: 0 | F4: 0 | G4: 0 | H4: 3 | I4: 0 | J4: =SUM(D4:I4) -> 3
A5: Фаза 0 — Фундамент (инфра + token-server с нуля) | B5: CI/CD с нуля (GHA build/push/deploy, GHCR, rollback) | C5: DevOps | D5: 0 | E5: 0 | F5: 0 | G5: 0 | H5: 2 | I5: 0 | J5: =SUM(D5:I5) -> 2
A6: Фаза 0 — Фундамент (инфра + token-server с нуля) | B6: Hardening (secrets-manager, fail2ban, unattended-upgrades, log-rotation, supply-chain/scan) | C6: DevOps | D6: 0 | E6: 0 | F6: 0 | G6: 0 | H6: 6 | I6: 0 | J6: =SUM(D6:I6) -> 6
A7: Фаза 0 — Фундамент (инфра + token-server с нуля) | B7: Мониторинг и алертинг (Prometheus+Grafana, Alertmanager, Uptime, Sentry) | C7: DevOps | D7: 0 | E7: 0 | F7: 0 | G7: 0 | H7: 6 | I7: 0 | J7: =SUM(D7:I7) -> 6
A8: Фаза 0 — Фундамент (инфра + token-server с нуля) | B8: Backups (Redis RDB + offsite, restore-drill) | C8: DevOps | D8: 0 | E8: 0 | F8: 0 | G8: 0 | H8: 1.5 | I8: 0 | J8: =SUM(D8:I8) -> 1.5
A9: Фаза 0 — Фундамент (инфра + token-server с нуля) | B9: Token-server с нуля: scaffolding + session API + fail-fast config | C9: Backend | D9: 0 | E9: 0 | F9: 2 | G9: 0 | H9: 0 | I9: 0 | J9: =SUM(D9:I9) -> 2
A10: Фаза 0 — Фундамент (инфра + token-server с нуля) | B10: Token-server: коды (CSPRNG) + Redis-mapping/TTL + create/end + LiveKit RoomService | C10: Backend | D10: 0 | E10: 0 | F10: 3.5 | G10: 0 | H10: 0 | I10: 0 | J10: =SUM(D10:I10) -> 3.5
A11: Фаза 0 — Фундамент (инфра + token-server с нуля) | B11: Token-server: agent/join + anti-hijack + идемпотентность + rate-limit + CORS + logging + health | C11: Backend | D11: 0 | E11: 0 | F11: 4 | G11: 0 | H11: 0 | I11: 0 | J11: =SUM(D11:I11) -> 4
A12: Фаза 0 — Фундамент (инфра + token-server с нуля) | B12: JWT (publisher/subscriber scoped, TTL, revocation) | C12: Backend | D12: 0 | E12: 0 | F12: 2 | G12: 0 | H12: 0 | I12: 0 | J12: =SUM(D12:I12) -> 2
A13: Фаза 0 — Фундамент (инфра + token-server с нуля) | B13: Auth-интеграция (переиспользуем host SSO): verify, agentId, RBAC, audit | C13: Backend | D13: 0 | E13: 0 | F13: 2.5 | G13: 0 | H13: 0 | I13: 0 | J13: =SUM(D13:I13) -> 2.5
A14: Фаза 0 — Фундамент (инфра + token-server с нуля) | B14: Запись: Egress lifecycle-hooks + retention/GDPR-delete (BE) + Egress infra + S3/at-rest (DevOps) | C14: Backend, DevOps | D14: 0 | E14: 0 | F14: 3.5 | G14: 0 | H14: 3 | I14: 0 | J14: =SUM(D14:I14) -> 6.5
A15: Фаза 0 — Фундамент (инфра + token-server с нуля) | B15: Reliability (graceful deploy, DoS-basic, healthchecks, runbook) | C15: DevOps, Backend | D15: 0 | E15: 0 | F15: 1 | G15: 0 | H15: 2.5 | I15: 0 | J15: =SUM(D15:I15) -> 3.5
... A39: Фаза 5 — Кросс-платформенный launch | B39: GDPR sign-off + runbook + bug-buffer | C39: QA | D39: 0 | E39: 0 | F39: 0 | G39: 0 | H39: 0 | I39: 2 | J39: =SUM(D39:I39) -> 2
B40: ИТОГО (core) | D40: =SUM(D4:D39) -> 20 | E40: =SUM(E4:E39) -> 15.5 | F40: =SUM(F4:F39) -> 24 | G40: =SUM(G4:G39) -> 27.5 | H40: =SUM(H4:H39) -> 26 | I40: =SUM(I4:I39) -> 19.5 | J40: =SUM(J4:J39) -> 132.5
B42: Известный долг (вне текущей оценки)
B43: PII-redaction | C43: +10–20 чел-дней; вероятно обязателен при финсектор/healthcare-клиенте
B44: Настоящий remote control | C44: +8–16 чел-дней, R&D; input-injection в песочнице недоступен 3rd-party
B45: DOM-mirroring для Web | C45: +30–40 чел-дней; другая архитектура
B46: HA / мульти-регион, пентест, сертификация | C46: отдельные бюджеты/треки

Sheet Инфра
A1: Инфраструктура — стоимость (self-hosted, Hetzner)
A3: Recurring (в месяц)
A4: Позиция | B4: €/мес (низ) | C4: €/мес (верх) | D4: Комментарий
A5: Compute: CCX23 (4 dedicated vCPU / 16 GB) | B5: 25 | C5: 25 | D5: dedicated vCPU безопаснее для WebRTC-медиа
A6: Object storage (записи + бэкапы) | B6: 6 | C6: 15 | D6: Hetzner Object Storage; растёт с retention
A7: Aux-нода (мониторинг / egress) или co-locate | B7: 0 | C7: 11 | D7: co-locate = €0
A8: TURN (coturn co-located) / DNS (Cloudflare) | B8: 0 | C8: 0 | D8: co-located; Cloudflare DNS free
A9: Резерв на bandwidth overflow | B9: 0 | C9: 10 | D9: 20 TB включено в тариф ноды
A10: Итого / мес | B10: =SUM(B5:B9) -> 31 | C10: =SUM(C5:C9) -> 61
A11: Итого / год | B11: =B10*12 -> 372 | C11: =C10*12 -> 732
A13: Разовые / годовые
A14: Позиция | B14: € | D14: Комментарий
A15: Apple Developer Program | B15: 99 | D15: в год
A16: Google Play Developer | B16: 25 | D16: разово
A17: Юр. ревью consent / DPA / privacy | B17: 1500 | D17: внутри или ~€1000–2000 внешне
A20: Вывод: бюджет программы определяется инженерным временем, не инфрой (recurring ≈ €35–70/мес).

Sheet Гант
A1: Диаграмма Ганта — команда 4–5 человек (недели)
A3: # | B3: Задача | C3: Роли | D3: Старт | E3: Длит. | F3: 1 | G3: 2 | H3: 3 | I3: 4 | J3: 5 | K3: 6 | L3: 7 | M3: 8 | N3: 9 | O3: 10 | P3: 11 | Q3: 12 | R3: 13 | S3: 14 | T3: 15 | U3: 16
B4: Фаза 0 — Фундамент (инфра + token-server)
A5: 1 | B5: Базовая инфра + CI/CD (с нуля) | C5: DevOps | D5: 1 | E5: 3
A6: 2 | B6: Token-server core (API/коды/join/JWT) | C6: Backend | D6: 1 | E6: 4
A7: 3 | B7: Hardening + мониторинг + backups | C7: DevOps | D7: 3 | E7: 4
A8: 4 | B8: Auth-интеграция + Egress + reliability + автотесты | C8: Backend | D8: 4 | E8: 3
A9: 5 | B9: Security/GDPR + shared | C9: Backend, QA | D9: 5 | E9: 2
B10: Фаза 1 — iOS-клиент (с нуля)
A11: 6 | B11: iOS SDK core (capture/publish/transport/state) | C11: iOS | D11: 4 | E11: 4
A12: 7 | B12: Reconnect + аннотации + тесты + device QA | C12: iOS, QA | D12: 7 | E12: 3
B13: Фаза 2 — Android-клиент (с нуля)
A14: 8 | B14: Android SDK (MediaProjection + foreground svc) | C14: Android | D14: 5 | E14: 4
A15: 9 | B15: Feature-parity + QA фрагментация | C15: Android, QA | D15: 9 | E15: 2
B16: Фаза 3 — Оператор в существующем React
A17: 10 | B17: Интеграция + viewer + аннотации | C17: Frontend | D17: 5 | E17: 3
A18: 11 | B18: Playback + auth + integration QA | C18: Frontend, QA | D18: 8 | E18: 1
B19: Фаза 4 — Web-клиент (screen-share)
A20: 12 | B20: Web-клиент (getDisplayMedia) | C20: Frontend/Web | D20: 6 | E20: 3
A21: 13 | B21: Cross-browser QA | C21: QA | D21: 9 | E21: 1
B22: Фаза 5 — Кросс-платформенный launch
A23: 14 | B23: Load-test 50 сессий (mixed) | C23: DevOps, QA | D23: 11 | E23: 2
A24: 15 | B24: GDPR sign-off + runbook + buffer | C24: QA | D24: 12 | E24: 2
B26: ◆ Прод-релиз ≈ конец недели 13
B27: Полосы = загрузка фазы. Старт/Длит. (жёлтые) — входные: меняйте, полосы двигаются.
B29: Легенда: | C29: Ф.0 | D29: Ф.1 | E29: Ф.2 | F29: Ф.3 | G29: Ф.4 | H29: Ф.5
